Using the latest cached version of the dataset since flwrlabs/pacs couldn't be found on the Hugging Face Hub
Found the latest cached dataset configuration 'default' at /home/apiasecz/.cache/huggingface/datasets/flwrlabs___pacs/default/0.0.0/394113073258ead631f617d2e13bb377c0715c4b (last modified on Wed Jan 29 16:59:35 2025).
Using the latest cached version of the dataset since flwrlabs/pacs couldn't be found on the Hugging Face Hub
Found the latest cached dataset configuration 'default' at /home/apiasecz/.cache/huggingface/datasets/flwrlabs___pacs/default/0.0.0/394113073258ead631f617d2e13bb377c0715c4b (last modified on Wed Jan 29 16:59:35 2025).
Using the latest cached version of the dataset since flwrlabs/pacs couldn't be found on the Hugging Face Hub
Found the latest cached dataset configuration 'default' at /home/apiasecz/.cache/huggingface/datasets/flwrlabs___pacs/default/0.0.0/394113073258ead631f617d2e13bb377c0715c4b (last modified on Wed Jan 29 16:59:35 2025).
Device: cuda
CUDA Version: 12.1
cuDNN Version: 8902
PyTorch Version: 2.3.0

Model used: PACSCNN
Initial dataset creation
Initial dataset creation
Initial loss: 25.70623016357422
<__main__.Policy object at 0x1516aae17080>
25.70623016357422
Loss historical diff: 2.7237653732299805; Loss Difference: 0.0, Decision: 1
Traceback (most recent call last):
  File "/home/apiasecz/programming/concept_drift_optimal_adaptation_FL/src/execute/evaluate_policy.py", line 753, in <module>
    main()
  File "/home/apiasecz/programming/concept_drift_optimal_adaptation_FL/src/execute/evaluate_policy.py", line 733, in main
    evaluate_policy_under_drift(
  File "/home/apiasecz/programming/concept_drift_optimal_adaptation_FL/src/execute/evaluate_policy.py", line 554, in evaluate_policy_under_drift
    update_loss = agent_train.update_steps(
                  ^^^^^^^^^^^^^^^^^^^^^^^^^
  File "/home/apiasecz/programming/Federated_Learning_Base_Toolkit_torch/fl_toolkit/federated/client.py", line 202, in update_steps
    return self.model.update_steps(self.data_loader, optimizer, loss_fn, num_updates, verbose)
           ^^^^^^^^^^^^^^^^^^^^^^^^^^^^^^^^^^^^^^^^^^^^^^^^^^^^^^^^^^^^^^^^^^^^^^^^^^^^^^^^^^^
  File "/home/apiasecz/programming/Federated_Learning_Base_Toolkit_torch/fl_toolkit/models/base_model.py", line 77, in update_steps
    loss.backward()
  File "/home/apiasecz/.conda/envs/cog_fl_llm_env/lib/python3.12/site-packages/torch/_tensor.py", line 525, in backward
    torch.autograd.backward(
  File "/home/apiasecz/.conda/envs/cog_fl_llm_env/lib/python3.12/site-packages/torch/autograd/__init__.py", line 267, in backward
    _engine_run_backward(
  File "/home/apiasecz/.conda/envs/cog_fl_llm_env/lib/python3.12/site-packages/torch/autograd/graph.py", line 744, in _engine_run_backward
    return Variable._execution_engine.run_backward(  # Calls into the C++ engine to run the backward pass
           ^^^^^^^^^^^^^^^^^^^^^^^^^^^^^^^^^^^^^^^^^^^^^^^^^^^^^^^^^^^^^^^^^^^^^^^^^^^^^^^^^^^^^^^^^^^^^^
RuntimeError: cuDNN error: CUDNN_STATUS_NOT_INITIALIZED
Exception in thread Thread-5 (_pin_memory_loop):
Traceback (most recent call last):
  File "/home/apiasecz/.conda/envs/cog_fl_llm_env/lib/python3.12/threading.py", line 1073, in _bootstrap_inner
    self.run()
  File "/home/apiasecz/.conda/envs/cog_fl_llm_env/lib/python3.12/threading.py", line 1010, in run
    self._target(*self._args, **self._kwargs)
  File "/home/apiasecz/.conda/envs/cog_fl_llm_env/lib/python3.12/site-packages/torch/utils/data/_utils/pin_memory.py", line 54, in _pin_memory_loop
    do_one_step()
  File "/home/apiasecz/.conda/envs/cog_fl_llm_env/lib/python3.12/site-packages/torch/utils/data/_utils/pin_memory.py", line 31, in do_one_step
    r = in_queue.get(timeout=MP_STATUS_CHECK_INTERVAL)
        ^^^^^^^^^^^^^^^^^^^^^^^^^^^^^^^^^^^^^^^^^^^^^^
  File "/home/apiasecz/.conda/envs/cog_fl_llm_env/lib/python3.12/multiprocessing/queues.py", line 122, in get
    return _ForkingPickler.loads(res)
           ^^^^^^^^^^^^^^^^^^^^^^^^^^
  File "/home/apiasecz/.conda/envs/cog_fl_llm_env/lib/python3.12/site-packages/torch/multiprocessing/reductions.py", line 495, in rebuild_storage_fd
    fd = df.detach()
         ^^^^^^^^^^^
  File "/home/apiasecz/.conda/envs/cog_fl_llm_env/lib/python3.12/multiprocessing/resource_sharer.py", line 57, in detach
    with _resource_sharer.get_connection(self._id) as conn:
         ^^^^^^^^^^^^^^^^^^^^^^^^^^^^^^^^^^^^^^^^^
  File "/home/apiasecz/.conda/envs/cog_fl_llm_env/lib/python3.12/multiprocessing/resource_sharer.py", line 86, in get_connection
    c = Client(address, authkey=process.current_process().authkey)
        ^^^^^^^^^^^^^^^^^^^^^^^^^^^^^^^^^^^^^^^^^^^^^^^^^^^^^^^^^^
  File "/home/apiasecz/.conda/envs/cog_fl_llm_env/lib/python3.12/multiprocessing/connection.py", line 525, in Client
    answer_challenge(c, authkey)
  File "/home/apiasecz/.conda/envs/cog_fl_llm_env/lib/python3.12/multiprocessing/connection.py", line 953, in answer_challenge
    message = connection.recv_bytes(256)         # reject large message
              ^^^^^^^^^^^^^^^^^^^^^^^^^^
  File "/home/apiasecz/.conda/envs/cog_fl_llm_env/lib/python3.12/multiprocessing/connection.py", line 216, in recv_bytes
    buf = self._recv_bytes(maxlength)
          ^^^^^^^^^^^^^^^^^^^^^^^^^^^
  File "/home/apiasecz/.conda/envs/cog_fl_llm_env/lib/python3.12/multiprocessing/connection.py", line 430, in _recv_bytes
    buf = self._recv(4)
          ^^^^^^^^^^^^^
  File "/home/apiasecz/.conda/envs/cog_fl_llm_env/lib/python3.12/multiprocessing/connection.py", line 395, in _recv
    chunk = read(handle, remaining)
            ^^^^^^^^^^^^^^^^^^^^^^^
ConnectionResetError: [Errno 104] Connection reset by peer
