HTTP Error 429 thrown while requesting HEAD https://huggingface.co/datasets/flwrlabs/pacs/resolve/main/README.md
Retrying in 1s [Retry 1/5].
HTTP Error 429 thrown while requesting HEAD https://huggingface.co/datasets/flwrlabs/pacs/resolve/main/README.md
Retrying in 2s [Retry 2/5].
HTTP Error 429 thrown while requesting HEAD https://huggingface.co/datasets/flwrlabs/pacs/resolve/main/README.md
Retrying in 4s [Retry 3/5].
HTTP Error 429 thrown while requesting HEAD https://huggingface.co/datasets/flwrlabs/pacs/resolve/main/README.md
Retrying in 8s [Retry 4/5].
HTTP Error 429 thrown while requesting HEAD https://huggingface.co/datasets/flwrlabs/pacs/resolve/main/README.md
Retrying in 8s [Retry 5/5].
HTTP Error 429 thrown while requesting HEAD https://huggingface.co/datasets/flwrlabs/pacs/resolve/main/README.md
HTTP Error 429 thrown while requesting HEAD https://huggingface.co/datasets/flwrlabs/pacs/resolve/394113073258ead631f617d2e13bb377c0715c4b/pacs.py
Retrying in 1s [Retry 1/5].
HTTP Error 429 thrown while requesting HEAD https://huggingface.co/datasets/flwrlabs/pacs/resolve/394113073258ead631f617d2e13bb377c0715c4b/pacs.py
Retrying in 2s [Retry 2/5].
HTTP Error 429 thrown while requesting HEAD https://huggingface.co/datasets/flwrlabs/pacs/resolve/394113073258ead631f617d2e13bb377c0715c4b/pacs.py
Retrying in 4s [Retry 3/5].
HTTP Error 429 thrown while requesting HEAD https://huggingface.co/datasets/flwrlabs/pacs/resolve/394113073258ead631f617d2e13bb377c0715c4b/pacs.py
Retrying in 8s [Retry 4/5].
HTTP Error 429 thrown while requesting HEAD https://huggingface.co/datasets/flwrlabs/pacs/resolve/394113073258ead631f617d2e13bb377c0715c4b/pacs.py
Retrying in 8s [Retry 5/5].
HTTP Error 429 thrown while requesting HEAD https://huggingface.co/datasets/flwrlabs/pacs/resolve/394113073258ead631f617d2e13bb377c0715c4b/pacs.py
Using the latest cached version of the dataset since flwrlabs/pacs couldn't be found on the Hugging Face Hub
Found the latest cached dataset configuration 'default' at /home/apiasecz/.cache/huggingface/datasets/flwrlabs___pacs/default/0.0.0/394113073258ead631f617d2e13bb377c0715c4b (last modified on Wed Jan 29 16:59:35 2025).
HTTP Error 429 thrown while requesting HEAD https://huggingface.co/datasets/flwrlabs/pacs/resolve/main/README.md
Retrying in 1s [Retry 1/5].
HTTP Error 429 thrown while requesting HEAD https://huggingface.co/datasets/flwrlabs/pacs/resolve/main/README.md
Retrying in 2s [Retry 2/5].
HTTP Error 429 thrown while requesting HEAD https://huggingface.co/datasets/flwrlabs/pacs/resolve/main/README.md
Retrying in 4s [Retry 3/5].
HTTP Error 429 thrown while requesting HEAD https://huggingface.co/datasets/flwrlabs/pacs/resolve/main/README.md
Retrying in 8s [Retry 4/5].
HTTP Error 429 thrown while requesting HEAD https://huggingface.co/datasets/flwrlabs/pacs/resolve/main/README.md
Retrying in 8s [Retry 5/5].
HTTP Error 429 thrown while requesting HEAD https://huggingface.co/datasets/flwrlabs/pacs/resolve/main/README.md
HTTP Error 429 thrown while requesting HEAD https://huggingface.co/datasets/flwrlabs/pacs/resolve/394113073258ead631f617d2e13bb377c0715c4b/pacs.py
Retrying in 1s [Retry 1/5].
HTTP Error 429 thrown while requesting HEAD https://huggingface.co/datasets/flwrlabs/pacs/resolve/394113073258ead631f617d2e13bb377c0715c4b/pacs.py
Retrying in 2s [Retry 2/5].
HTTP Error 429 thrown while requesting HEAD https://huggingface.co/datasets/flwrlabs/pacs/resolve/394113073258ead631f617d2e13bb377c0715c4b/pacs.py
Retrying in 4s [Retry 3/5].
HTTP Error 429 thrown while requesting HEAD https://huggingface.co/datasets/flwrlabs/pacs/resolve/394113073258ead631f617d2e13bb377c0715c4b/pacs.py
Retrying in 8s [Retry 4/5].
HTTP Error 429 thrown while requesting HEAD https://huggingface.co/datasets/flwrlabs/pacs/resolve/394113073258ead631f617d2e13bb377c0715c4b/pacs.py
Retrying in 8s [Retry 5/5].
HTTP Error 429 thrown while requesting HEAD https://huggingface.co/datasets/flwrlabs/pacs/resolve/394113073258ead631f617d2e13bb377c0715c4b/pacs.py
Using the latest cached version of the dataset since flwrlabs/pacs couldn't be found on the Hugging Face Hub
Found the latest cached dataset configuration 'default' at /home/apiasecz/.cache/huggingface/datasets/flwrlabs___pacs/default/0.0.0/394113073258ead631f617d2e13bb377c0715c4b (last modified on Wed Jan 29 16:59:35 2025).
HTTP Error 429 thrown while requesting HEAD https://huggingface.co/datasets/flwrlabs/pacs/resolve/main/README.md
Retrying in 1s [Retry 1/5].
HTTP Error 429 thrown while requesting HEAD https://huggingface.co/datasets/flwrlabs/pacs/resolve/main/README.md
Retrying in 2s [Retry 2/5].
HTTP Error 429 thrown while requesting HEAD https://huggingface.co/datasets/flwrlabs/pacs/resolve/main/README.md
Retrying in 4s [Retry 3/5].
HTTP Error 429 thrown while requesting HEAD https://huggingface.co/datasets/flwrlabs/pacs/resolve/main/README.md
Retrying in 8s [Retry 4/5].
HTTP Error 429 thrown while requesting HEAD https://huggingface.co/datasets/flwrlabs/pacs/resolve/main/README.md
Retrying in 8s [Retry 5/5].
HTTP Error 429 thrown while requesting HEAD https://huggingface.co/datasets/flwrlabs/pacs/resolve/main/README.md
HTTP Error 429 thrown while requesting HEAD https://huggingface.co/datasets/flwrlabs/pacs/resolve/394113073258ead631f617d2e13bb377c0715c4b/pacs.py
Retrying in 1s [Retry 1/5].
HTTP Error 429 thrown while requesting HEAD https://huggingface.co/datasets/flwrlabs/pacs/resolve/394113073258ead631f617d2e13bb377c0715c4b/pacs.py
Retrying in 2s [Retry 2/5].
HTTP Error 429 thrown while requesting HEAD https://huggingface.co/datasets/flwrlabs/pacs/resolve/394113073258ead631f617d2e13bb377c0715c4b/pacs.py
Retrying in 4s [Retry 3/5].
HTTP Error 429 thrown while requesting HEAD https://huggingface.co/datasets/flwrlabs/pacs/resolve/394113073258ead631f617d2e13bb377c0715c4b/pacs.py
Retrying in 8s [Retry 4/5].
HTTP Error 429 thrown while requesting HEAD https://huggingface.co/datasets/flwrlabs/pacs/resolve/394113073258ead631f617d2e13bb377c0715c4b/pacs.py
Retrying in 8s [Retry 5/5].
HTTP Error 429 thrown while requesting HEAD https://huggingface.co/datasets/flwrlabs/pacs/resolve/394113073258ead631f617d2e13bb377c0715c4b/pacs.py
Using the latest cached version of the dataset since flwrlabs/pacs couldn't be found on the Hugging Face Hub
Found the latest cached dataset configuration 'default' at /home/apiasecz/.cache/huggingface/datasets/flwrlabs___pacs/default/0.0.0/394113073258ead631f617d2e13bb377c0715c4b (last modified on Wed Jan 29 16:59:35 2025).
Device: cuda
CUDA Version: 12.1
cuDNN Version: 8902
PyTorch Version: 2.3.0

Model used: PACSCNN
Initial dataset creation
Initial dataset creation
Initial loss: 8.656878471374512
<__main__.Policy object at 0x14b0cad209b0>
8.656878471374512
Loss historical diff: 0.0; Loss Difference: 0.0, Decision: 0
Round 1 took 4.808502435684204s, results:
{'t': 0, 'current_accuracy': 0.17578125, 'current_loss': 8.38653826713562, 'train_loss': None, 'decision': 0, 'drift_rate': 0.016, 'target_domains': ['sketch']}
Loss historical diff: 0.0; Loss Difference: 0.0, Decision: 0
Round 2 took 5.03186559677124s, results:
{'t': 1, 'current_accuracy': 0.17578125, 'current_loss': 8.380846977233887, 'train_loss': None, 'decision': 0, 'drift_rate': 0.016, 'target_domains': ['sketch']}
Loss historical diff: 0.049874305725097656; Loss Difference: 0.0, Decision: 0
Round 3 took 4.4266767501831055s, results:
{'t': 2, 'current_accuracy': 0.17578125, 'current_loss': 8.430721282958984, 'train_loss': None, 'decision': 0, 'drift_rate': 0.016, 'target_domains': ['sketch']}
Loss historical diff: 0.0; Loss Difference: 0.0, Decision: 0
Round 4 took 4.178999185562134s, results:
{'t': 3, 'current_accuracy': 0.17578125, 'current_loss': 8.372424364089966, 'train_loss': None, 'decision': 0, 'drift_rate': 0.016, 'target_domains': ['sketch']}
Loss historical diff: 0.039552927017211914; Loss Difference: 0.0, Decision: 0
Round 5 took 4.194135427474976s, results:
{'t': 4, 'current_accuracy': 0.171875, 'current_loss': 8.411977291107178, 'train_loss': None, 'decision': 0, 'drift_rate': 0.016, 'target_domains': ['sketch']}
Loss historical diff: 0.07182860374450684; Loss Difference: 0.0, Decision: 1
/home/apiasecz/.conda/envs/cog_fl_llm_env/lib/python3.12/site-packages/torch/nn/modules/conv.py:456: UserWarning: Plan failed with an OutOfMemoryError: CUDA out of memory. Tried to allocate 1.00 GiB. GPU  (Triggered internally at /opt/conda/conda-bld/pytorch_1712608847532/work/aten/src/ATen/native/cudnn/Conv_v8.cpp:924.)
  return F.conv2d(input, weight, bias, self.stride,
/home/apiasecz/.conda/envs/cog_fl_llm_env/lib/python3.12/site-packages/torch/nn/modules/conv.py:456: UserWarning: Plan failed with an OutOfMemoryError: CUDA out of memory. Tried to allocate 514.00 MiB. GPU  (Triggered internally at /opt/conda/conda-bld/pytorch_1712608847532/work/aten/src/ATen/native/cudnn/Conv_v8.cpp:924.)
  return F.conv2d(input, weight, bias, self.stride,
/home/apiasecz/.conda/envs/cog_fl_llm_env/lib/python3.12/site-packages/torch/nn/modules/conv.py:456: UserWarning: Plan failed with an OutOfMemoryError: CUDA out of memory. Tried to allocate 258.00 MiB. GPU  (Triggered internally at /opt/conda/conda-bld/pytorch_1712608847532/work/aten/src/ATen/native/cudnn/Conv_v8.cpp:924.)
  return F.conv2d(input, weight, bias, self.stride,
/home/apiasecz/.conda/envs/cog_fl_llm_env/lib/python3.12/site-packages/torch/nn/modules/conv.py:456: UserWarning: Plan failed with an OutOfMemoryError: CUDA out of memory. Tried to allocate 516.00 MiB. GPU  (Triggered internally at /opt/conda/conda-bld/pytorch_1712608847532/work/aten/src/ATen/native/cudnn/Conv_v8.cpp:924.)
  return F.conv2d(input, weight, bias, self.stride,
/home/apiasecz/.conda/envs/cog_fl_llm_env/lib/python3.12/site-packages/torch/nn/modules/conv.py:456: UserWarning: Plan failed with an OutOfMemoryError: CUDA out of memory. Tried to allocate 770.00 MiB. GPU  (Triggered internally at /opt/conda/conda-bld/pytorch_1712608847532/work/aten/src/ATen/native/cudnn/Conv_v8.cpp:924.)
  return F.conv2d(input, weight, bias, self.stride,
Traceback (most recent call last):
  File "/home/apiasecz/programming/concept_drift_optimal_adaptation_FL/src/execute/evaluate_policy.py", line 753, in <module>
    main()
  File "/home/apiasecz/programming/concept_drift_optimal_adaptation_FL/src/execute/evaluate_policy.py", line 733, in main
    evaluate_policy_under_drift(
  File "/home/apiasecz/programming/concept_drift_optimal_adaptation_FL/src/execute/evaluate_policy.py", line 554, in evaluate_policy_under_drift
    update_loss = agent_train.update_steps(
                  ^^^^^^^^^^^^^^^^^^^^^^^^^
  File "/home/apiasecz/programming/Federated_Learning_Base_Toolkit_torch/fl_toolkit/federated/client.py", line 202, in update_steps
    return self.model.update_steps(self.data_loader, optimizer, loss_fn, num_updates, verbose)
           ^^^^^^^^^^^^^^^^^^^^^^^^^^^^^^^^^^^^^^^^^^^^^^^^^^^^^^^^^^^^^^^^^^^^^^^^^^^^^^^^^^^
  File "/home/apiasecz/programming/Federated_Learning_Base_Toolkit_torch/fl_toolkit/models/base_model.py", line 93, in update_steps
    outputs = self.model(inputs)
              ^^^^^^^^^^^^^^^^^^
  File "/home/apiasecz/.conda/envs/cog_fl_llm_env/lib/python3.12/site-packages/torch/nn/modules/module.py", line 1532, in _wrapped_call_impl
    return self._call_impl(*args, **kwargs)
           ^^^^^^^^^^^^^^^^^^^^^^^^^^^^^^^^
  File "/home/apiasecz/.conda/envs/cog_fl_llm_env/lib/python3.12/site-packages/torch/nn/modules/module.py", line 1541, in _call_impl
    return forward_call(*args, **kwargs)
           ^^^^^^^^^^^^^^^^^^^^^^^^^^^^^
  File "/home/apiasecz/programming/concept_drift_optimal_adaptation_FL/src/execute/evaluate_policy.py", line 47, in forward
    x = self.features(x)
        ^^^^^^^^^^^^^^^^
  File "/home/apiasecz/.conda/envs/cog_fl_llm_env/lib/python3.12/site-packages/torch/nn/modules/module.py", line 1532, in _wrapped_call_impl
    return self._call_impl(*args, **kwargs)
           ^^^^^^^^^^^^^^^^^^^^^^^^^^^^^^^^
  File "/home/apiasecz/.conda/envs/cog_fl_llm_env/lib/python3.12/site-packages/torch/nn/modules/module.py", line 1541, in _call_impl
    return forward_call(*args, **kwargs)
           ^^^^^^^^^^^^^^^^^^^^^^^^^^^^^
  File "/home/apiasecz/.conda/envs/cog_fl_llm_env/lib/python3.12/site-packages/torch/nn/modules/container.py", line 217, in forward
    input = module(input)
            ^^^^^^^^^^^^^
  File "/home/apiasecz/.conda/envs/cog_fl_llm_env/lib/python3.12/site-packages/torch/nn/modules/module.py", line 1532, in _wrapped_call_impl
    return self._call_impl(*args, **kwargs)
           ^^^^^^^^^^^^^^^^^^^^^^^^^^^^^^^^
  File "/home/apiasecz/.conda/envs/cog_fl_llm_env/lib/python3.12/site-packages/torch/nn/modules/module.py", line 1541, in _call_impl
    return forward_call(*args, **kwargs)
           ^^^^^^^^^^^^^^^^^^^^^^^^^^^^^
  File "/home/apiasecz/programming/concept_drift_optimal_adaptation_FL/src/execute/evaluate_policy.py", line 70, in forward
    out = self.bn1(out)
          ^^^^^^^^^^^^^
  File "/home/apiasecz/.conda/envs/cog_fl_llm_env/lib/python3.12/site-packages/torch/nn/modules/module.py", line 1532, in _wrapped_call_impl
    return self._call_impl(*args, **kwargs)
           ^^^^^^^^^^^^^^^^^^^^^^^^^^^^^^^^
  File "/home/apiasecz/.conda/envs/cog_fl_llm_env/lib/python3.12/site-packages/torch/nn/modules/module.py", line 1541, in _call_impl
    return forward_call(*args, **kwargs)
           ^^^^^^^^^^^^^^^^^^^^^^^^^^^^^
  File "/home/apiasecz/.conda/envs/cog_fl_llm_env/lib/python3.12/site-packages/torch/nn/modules/batchnorm.py", line 175, in forward
    return F.batch_norm(
           ^^^^^^^^^^^^^
  File "/home/apiasecz/.conda/envs/cog_fl_llm_env/lib/python3.12/site-packages/torch/nn/functional.py", line 2509, in batch_norm
    return torch.batch_norm(
           ^^^^^^^^^^^^^^^^^
torch.cuda.OutOfMemoryError: CUDA out of memory. Tried to allocate 256.00 MiB. GPU 
