Using the latest cached version of the dataset since flwrlabs/pacs couldn't be found on the Hugging Face Hub
Found the latest cached dataset configuration 'default' at /home/apiasecz/.cache/huggingface/datasets/flwrlabs___pacs/default/0.0.0/394113073258ead631f617d2e13bb377c0715c4b (last modified on Wed Jan 29 16:59:35 2025).
Device: cuda
CUDA Version: 12.1
cuDNN Version: 8902
PyTorch Version: 2.3.0
Model used: PACSCNN_4
Client device: cuda
PACSCNN_4
Traceback (most recent call last):
  File "/home/apiasecz/programming/concept_drift_optimal_adaptation_FL/src/execute/test_loss_behavior_under_drift.py", line 889, in <module>
    main()
  File "/home/apiasecz/programming/concept_drift_optimal_adaptation_FL/src/execute/test_loss_behavior_under_drift.py", line 869, in main
    results = test_policy_under_drift(
              ^^^^^^^^^^^^^^^^^^^^^^^^
  File "/home/apiasecz/programming/concept_drift_optimal_adaptation_FL/src/execute/test_loss_behavior_under_drift.py", line 656, in test_policy_under_drift
    model.load_state_dict(torch.load(model_path))
                          ^^^^^^^^^^^^^^^^^^^^^^
  File "/home/apiasecz/.conda/envs/cog_fl_llm_env/lib/python3.12/site-packages/torch/serialization.py", line 997, in load
    with _open_file_like(f, 'rb') as opened_file:
         ^^^^^^^^^^^^^^^^^^^^^^^^
  File "/home/apiasecz/.conda/envs/cog_fl_llm_env/lib/python3.12/site-packages/torch/serialization.py", line 444, in _open_file_like
    return _open_file(name_or_buffer, mode)
           ^^^^^^^^^^^^^^^^^^^^^^^^^^^^^^^^
  File "/home/apiasecz/.conda/envs/cog_fl_llm_env/lib/python3.12/site-packages/torch/serialization.py", line 425, in __init__
    super().__init__(open(name, mode))
                     ^^^^^^^^^^^^^^^^
FileNotFoundError: [Errno 2] No such file or directory: '/scratch/gautschi/apiasecz/models/concept_drift_models/PACSCNN_4_sketch_img_size_128_seed_13.pth'
