Using the latest cached version of the dataset since flwrlabs/pacs couldn't be found on the Hugging Face Hub
Found the latest cached dataset configuration 'default' at /home/apiasecz/.cache/huggingface/datasets/flwrlabs___pacs/default/0.0.0/394113073258ead631f617d2e13bb377c0715c4b (last modified on Wed Jan 29 16:59:35 2025).
Using the latest cached version of the dataset since flwrlabs/pacs couldn't be found on the Hugging Face Hub
Found the latest cached dataset configuration 'default' at /home/apiasecz/.cache/huggingface/datasets/flwrlabs___pacs/default/0.0.0/394113073258ead631f617d2e13bb377c0715c4b (last modified on Wed Jan 29 16:59:35 2025).
Using the latest cached version of the dataset since flwrlabs/pacs couldn't be found on the Hugging Face Hub
Found the latest cached dataset configuration 'default' at /home/apiasecz/.cache/huggingface/datasets/flwrlabs___pacs/default/0.0.0/394113073258ead631f617d2e13bb377c0715c4b (last modified on Wed Jan 29 16:59:35 2025).
Device: cuda
CUDA Version: 12.1
cuDNN Version: 8902
PyTorch Version: 2.3.0

Model used: PACSCNN
Initial dataset creation
Initial dataset creation
Initial loss: 37.804439544677734
<__main__.Policy object at 0x1495dee6d6d0>
37.804439544677734
Loss historical diff: 0.39356422424316406; Loss Difference: 0.0, Decision: 1
/home/apiasecz/.conda/envs/cog_fl_llm_env/lib/python3.12/site-packages/torch/nn/modules/conv.py:456: UserWarning: Plan failed with an OutOfMemoryError: CUDA out of memory. Tried to allocate 386.00 MiB. GPU  (Triggered internally at /opt/conda/conda-bld/pytorch_1712608847532/work/aten/src/ATen/native/cudnn/Conv_v8.cpp:924.)
  return F.conv2d(input, weight, bias, self.stride,
/home/apiasecz/.conda/envs/cog_fl_llm_env/lib/python3.12/site-packages/torch/nn/modules/conv.py:456: UserWarning: Plan failed with an OutOfMemoryError: CUDA out of memory. Tried to allocate 260.00 MiB. GPU  (Triggered internally at /opt/conda/conda-bld/pytorch_1712608847532/work/aten/src/ATen/native/cudnn/Conv_v8.cpp:924.)
  return F.conv2d(input, weight, bias, self.stride,
/home/apiasecz/.conda/envs/cog_fl_llm_env/lib/python3.12/site-packages/torch/nn/modules/conv.py:456: UserWarning: Plan failed with an OutOfMemoryError: CUDA out of memory. Tried to allocate 198.00 MiB. GPU  (Triggered internally at /opt/conda/conda-bld/pytorch_1712608847532/work/aten/src/ATen/native/cudnn/Conv_v8.cpp:924.)
  return F.conv2d(input, weight, bias, self.stride,
Traceback (most recent call last):
  File "/home/apiasecz/programming/concept_drift_optimal_adaptation_FL/src/execute/evaluate_policy.py", line 753, in <module>
    main()
  File "/home/apiasecz/programming/concept_drift_optimal_adaptation_FL/src/execute/evaluate_policy.py", line 733, in main
    evaluate_policy_under_drift(
  File "/home/apiasecz/programming/concept_drift_optimal_adaptation_FL/src/execute/evaluate_policy.py", line 554, in evaluate_policy_under_drift
    update_loss = agent_train.update_steps(
                  ^^^^^^^^^^^^^^^^^^^^^^^^^
  File "/home/apiasecz/programming/Federated_Learning_Base_Toolkit_torch/fl_toolkit/federated/client.py", line 202, in update_steps
    return self.model.update_steps(self.data_loader, optimizer, loss_fn, num_updates, verbose)
           ^^^^^^^^^^^^^^^^^^^^^^^^^^^^^^^^^^^^^^^^^^^^^^^^^^^^^^^^^^^^^^^^^^^^^^^^^^^^^^^^^^^
  File "/home/apiasecz/programming/Federated_Learning_Base_Toolkit_torch/fl_toolkit/models/base_model.py", line 77, in update_steps
    loss.backward()
  File "/home/apiasecz/.conda/envs/cog_fl_llm_env/lib/python3.12/site-packages/torch/_tensor.py", line 525, in backward
    torch.autograd.backward(
  File "/home/apiasecz/.conda/envs/cog_fl_llm_env/lib/python3.12/site-packages/torch/autograd/__init__.py", line 267, in backward
    _engine_run_backward(
  File "/home/apiasecz/.conda/envs/cog_fl_llm_env/lib/python3.12/site-packages/torch/autograd/graph.py", line 744, in _engine_run_backward
    return Variable._execution_engine.run_backward(  # Calls into the C++ engine to run the backward pass
           ^^^^^^^^^^^^^^^^^^^^^^^^^^^^^^^^^^^^^^^^^^^^^^^^^^^^^^^^^^^^^^^^^^^^^^^^^^^^^^^^^^^^^^^^^^^^^^
RuntimeError: CUDA error: CUBLAS_STATUS_ALLOC_FAILED when calling `cublasCreate(handle)`
