Using the latest cached version of the dataset since flwrlabs/pacs couldn't be found on the Hugging Face Hub
Found the latest cached dataset configuration 'default' at /home/apiasecz/.cache/huggingface/datasets/flwrlabs___pacs/default/0.0.0/394113073258ead631f617d2e13bb377c0715c4b (last modified on Wed Jan 29 16:59:35 2025).
/home/apiasecz/.conda/envs/cog_fl_llm_env/lib/python3.12/site-packages/torch/nn/modules/conv.py:456: UserWarning: Plan failed with a cudnnException: CUDNN_BACKEND_EXECUTION_PLAN_DESCRIPTOR: cudnnFinalize Descriptor Failed cudnn_status: CUDNN_STATUS_NOT_SUPPORTED (Triggered internally at /opt/conda/conda-bld/pytorch_1712608847532/work/aten/src/ATen/native/cudnn/Conv_v8.cpp:919.)
  return F.conv2d(input, weight, bias, self.stride,
