HTTP Error 429 thrown while requesting HEAD https://huggingface.co/datasets/flwrlabs/pacs/resolve/main/README.md
Retrying in 1s [Retry 1/5].
HTTP Error 429 thrown while requesting HEAD https://huggingface.co/datasets/flwrlabs/pacs/resolve/main/README.md
Retrying in 2s [Retry 2/5].
HTTP Error 429 thrown while requesting HEAD https://huggingface.co/datasets/flwrlabs/pacs/resolve/main/README.md
Retrying in 4s [Retry 3/5].
HTTP Error 429 thrown while requesting HEAD https://huggingface.co/datasets/flwrlabs/pacs/resolve/main/README.md
Retrying in 8s [Retry 4/5].
HTTP Error 429 thrown while requesting HEAD https://huggingface.co/datasets/flwrlabs/pacs/resolve/main/README.md
Retrying in 8s [Retry 5/5].
HTTP Error 429 thrown while requesting HEAD https://huggingface.co/datasets/flwrlabs/pacs/resolve/main/README.md
HTTP Error 429 thrown while requesting HEAD https://huggingface.co/datasets/flwrlabs/pacs/resolve/394113073258ead631f617d2e13bb377c0715c4b/pacs.py
Retrying in 1s [Retry 1/5].
HTTP Error 429 thrown while requesting HEAD https://huggingface.co/datasets/flwrlabs/pacs/resolve/394113073258ead631f617d2e13bb377c0715c4b/pacs.py
Retrying in 2s [Retry 2/5].
HTTP Error 429 thrown while requesting HEAD https://huggingface.co/datasets/flwrlabs/pacs/resolve/394113073258ead631f617d2e13bb377c0715c4b/pacs.py
Retrying in 4s [Retry 3/5].
HTTP Error 429 thrown while requesting HEAD https://huggingface.co/datasets/flwrlabs/pacs/resolve/394113073258ead631f617d2e13bb377c0715c4b/pacs.py
Retrying in 8s [Retry 4/5].
HTTP Error 429 thrown while requesting HEAD https://huggingface.co/datasets/flwrlabs/pacs/resolve/394113073258ead631f617d2e13bb377c0715c4b/pacs.py
Retrying in 8s [Retry 5/5].
HTTP Error 429 thrown while requesting HEAD https://huggingface.co/datasets/flwrlabs/pacs/resolve/394113073258ead631f617d2e13bb377c0715c4b/pacs.py
Using the latest cached version of the dataset since flwrlabs/pacs couldn't be found on the Hugging Face Hub
Found the latest cached dataset configuration 'default' at /home/apiasecz/.cache/huggingface/datasets/flwrlabs___pacs/default/0.0.0/394113073258ead631f617d2e13bb377c0715c4b (last modified on Wed Jan 29 16:59:35 2025).
HTTP Error 429 thrown while requesting HEAD https://huggingface.co/datasets/flwrlabs/pacs/resolve/main/README.md
Retrying in 1s [Retry 1/5].
HTTP Error 429 thrown while requesting HEAD https://huggingface.co/datasets/flwrlabs/pacs/resolve/main/README.md
Retrying in 2s [Retry 2/5].
HTTP Error 429 thrown while requesting HEAD https://huggingface.co/datasets/flwrlabs/pacs/resolve/main/README.md
Retrying in 4s [Retry 3/5].
HTTP Error 429 thrown while requesting HEAD https://huggingface.co/datasets/flwrlabs/pacs/resolve/main/README.md
Retrying in 8s [Retry 4/5].
HTTP Error 429 thrown while requesting HEAD https://huggingface.co/datasets/flwrlabs/pacs/resolve/main/README.md
Retrying in 8s [Retry 5/5].
HTTP Error 429 thrown while requesting HEAD https://huggingface.co/datasets/flwrlabs/pacs/resolve/main/README.md
HTTP Error 429 thrown while requesting HEAD https://huggingface.co/datasets/flwrlabs/pacs/resolve/394113073258ead631f617d2e13bb377c0715c4b/pacs.py
Retrying in 1s [Retry 1/5].
HTTP Error 429 thrown while requesting HEAD https://huggingface.co/datasets/flwrlabs/pacs/resolve/394113073258ead631f617d2e13bb377c0715c4b/pacs.py
Retrying in 2s [Retry 2/5].
HTTP Error 429 thrown while requesting HEAD https://huggingface.co/datasets/flwrlabs/pacs/resolve/394113073258ead631f617d2e13bb377c0715c4b/pacs.py
Retrying in 4s [Retry 3/5].
HTTP Error 429 thrown while requesting HEAD https://huggingface.co/datasets/flwrlabs/pacs/resolve/394113073258ead631f617d2e13bb377c0715c4b/pacs.py
Retrying in 8s [Retry 4/5].
HTTP Error 429 thrown while requesting HEAD https://huggingface.co/datasets/flwrlabs/pacs/resolve/394113073258ead631f617d2e13bb377c0715c4b/pacs.py
Retrying in 8s [Retry 5/5].
HTTP Error 429 thrown while requesting HEAD https://huggingface.co/datasets/flwrlabs/pacs/resolve/394113073258ead631f617d2e13bb377c0715c4b/pacs.py
Using the latest cached version of the dataset since flwrlabs/pacs couldn't be found on the Hugging Face Hub
Found the latest cached dataset configuration 'default' at /home/apiasecz/.cache/huggingface/datasets/flwrlabs___pacs/default/0.0.0/394113073258ead631f617d2e13bb377c0715c4b (last modified on Wed Jan 29 16:59:35 2025).
HTTP Error 429 thrown while requesting HEAD https://huggingface.co/datasets/flwrlabs/pacs/resolve/main/README.md
Retrying in 1s [Retry 1/5].
HTTP Error 429 thrown while requesting HEAD https://huggingface.co/datasets/flwrlabs/pacs/resolve/main/README.md
Retrying in 2s [Retry 2/5].
HTTP Error 429 thrown while requesting HEAD https://huggingface.co/datasets/flwrlabs/pacs/resolve/main/README.md
Retrying in 4s [Retry 3/5].
HTTP Error 429 thrown while requesting HEAD https://huggingface.co/datasets/flwrlabs/pacs/resolve/main/README.md
Retrying in 8s [Retry 4/5].
HTTP Error 429 thrown while requesting HEAD https://huggingface.co/datasets/flwrlabs/pacs/resolve/main/README.md
Retrying in 8s [Retry 5/5].
HTTP Error 429 thrown while requesting HEAD https://huggingface.co/datasets/flwrlabs/pacs/resolve/main/README.md
HTTP Error 429 thrown while requesting HEAD https://huggingface.co/datasets/flwrlabs/pacs/resolve/394113073258ead631f617d2e13bb377c0715c4b/pacs.py
Retrying in 1s [Retry 1/5].
HTTP Error 429 thrown while requesting HEAD https://huggingface.co/datasets/flwrlabs/pacs/resolve/394113073258ead631f617d2e13bb377c0715c4b/pacs.py
Retrying in 2s [Retry 2/5].
HTTP Error 429 thrown while requesting HEAD https://huggingface.co/datasets/flwrlabs/pacs/resolve/394113073258ead631f617d2e13bb377c0715c4b/pacs.py
Retrying in 4s [Retry 3/5].
HTTP Error 429 thrown while requesting HEAD https://huggingface.co/datasets/flwrlabs/pacs/resolve/394113073258ead631f617d2e13bb377c0715c4b/pacs.py
Retrying in 8s [Retry 4/5].
HTTP Error 429 thrown while requesting HEAD https://huggingface.co/datasets/flwrlabs/pacs/resolve/394113073258ead631f617d2e13bb377c0715c4b/pacs.py
Retrying in 8s [Retry 5/5].
HTTP Error 429 thrown while requesting HEAD https://huggingface.co/datasets/flwrlabs/pacs/resolve/394113073258ead631f617d2e13bb377c0715c4b/pacs.py
Using the latest cached version of the dataset since flwrlabs/pacs couldn't be found on the Hugging Face Hub
Found the latest cached dataset configuration 'default' at /home/apiasecz/.cache/huggingface/datasets/flwrlabs___pacs/default/0.0.0/394113073258ead631f617d2e13bb377c0715c4b (last modified on Wed Jan 29 16:59:35 2025).
Device: cuda
CUDA Version: 12.1
cuDNN Version: 8902
PyTorch Version: 2.3.0

Model used: PACSCNN
Initial dataset creation
Initial dataset creation
Initial loss: 5.803514003753662
<__main__.Policy object at 0x147072b1e4b0>
5.803514003753662
Loss historical diff: 0.0; Loss Difference: 0.0, Decision: 0
Round 1 took 4.98175573348999s, results:
{'t': 0, 'current_accuracy': 0.30859375, 'current_loss': 5.757376432418823, 'train_loss': None, 'decision': 0, 'drift_rate': 0.016, 'target_domains': ['sketch']}
Loss historical diff: 0.026569843292236328; Loss Difference: 0.0, Decision: 0
Round 2 took 4.759124040603638s, results:
{'t': 1, 'current_accuracy': 0.3046875, 'current_loss': 5.78394627571106, 'train_loss': None, 'decision': 0, 'drift_rate': 0.016, 'target_domains': ['sketch']}
Loss historical diff: 0.022418975830078125; Loss Difference: 0.0, Decision: 0
Round 3 took 4.729853391647339s, results:
{'t': 2, 'current_accuracy': 0.30078125, 'current_loss': 5.779795408248901, 'train_loss': None, 'decision': 0, 'drift_rate': 0.016, 'target_domains': ['sketch']}
Loss historical diff: 0.0; Loss Difference: 0.0, Decision: 0
Round 4 took 5.091743469238281s, results:
{'t': 3, 'current_accuracy': 0.30078125, 'current_loss': 5.754971027374268, 'train_loss': None, 'decision': 0, 'drift_rate': 0.016, 'target_domains': ['sketch']}
Loss historical diff: 0.10859441757202148; Loss Difference: 0.0, Decision: 0
Round 5 took 4.718518495559692s, results:
{'t': 4, 'current_accuracy': 0.2890625, 'current_loss': 5.863565444946289, 'train_loss': None, 'decision': 0, 'drift_rate': 0.016, 'target_domains': ['sketch']}
Loss historical diff: 0.15762734413146973; Loss Difference: 0.0, Decision: 0
Round 6 took 4.594363689422607s, results:
{'t': 5, 'current_accuracy': 0.28515625, 'current_loss': 5.912598371505737, 'train_loss': None, 'decision': 0, 'drift_rate': 0.016, 'target_domains': ['sketch']}
Loss historical diff: 0.09940195083618164; Loss Difference: 0.0, Decision: 0
Round 7 took 4.652964115142822s, results:
{'t': 6, 'current_accuracy': 0.28515625, 'current_loss': 5.854372978210449, 'train_loss': None, 'decision': 0, 'drift_rate': 0.016, 'target_domains': ['sketch']}
Loss historical diff: 0.08452820777893066; Loss Difference: 0.0, Decision: 0
Round 8 took 5.024003505706787s, results:
{'t': 7, 'current_accuracy': 0.28515625, 'current_loss': 5.839499235153198, 'train_loss': None, 'decision': 0, 'drift_rate': 0.016, 'target_domains': ['sketch']}
Loss historical diff: 0.05380105972290039; Loss Difference: 0.0, Decision: 0
Round 9 took 5.091862201690674s, results:
{'t': 8, 'current_accuracy': 0.2890625, 'current_loss': 5.808772087097168, 'train_loss': None, 'decision': 0, 'drift_rate': 0.016, 'target_domains': ['sketch']}
Loss historical diff: 0.13928961753845215; Loss Difference: 0.0, Decision: 0
Round 10 took 4.810352087020874s, results:
{'t': 9, 'current_accuracy': 0.28125, 'current_loss': 5.89426064491272, 'train_loss': None, 'decision': 0, 'drift_rate': 0.016, 'target_domains': ['sketch']}
Loss historical diff: 0.1809861660003662; Loss Difference: 0.0, Decision: 0
Round 11 took 5.0698559284210205s, results:
{'t': 10, 'current_accuracy': 0.2734375, 'current_loss': 5.935957193374634, 'train_loss': None, 'decision': 0, 'drift_rate': 0.016, 'target_domains': ['sketch']}
Loss historical diff: 0.20670056343078613; Loss Difference: 0.0, Decision: 1
Traceback (most recent call last):
  File "/home/apiasecz/programming/concept_drift_optimal_adaptation_FL/src/execute/evaluate_policy.py", line 753, in <module>
    main()
  File "/home/apiasecz/programming/concept_drift_optimal_adaptation_FL/src/execute/evaluate_policy.py", line 733, in main
    evaluate_policy_under_drift(
  File "/home/apiasecz/programming/concept_drift_optimal_adaptation_FL/src/execute/evaluate_policy.py", line 554, in evaluate_policy_under_drift
    update_loss = agent_train.update_steps(
                  ^^^^^^^^^^^^^^^^^^^^^^^^^
  File "/home/apiasecz/programming/Federated_Learning_Base_Toolkit_torch/fl_toolkit/federated/client.py", line 202, in update_steps
    return self.model.update_steps(self.data_loader, optimizer, loss_fn, num_updates, verbose)
           ^^^^^^^^^^^^^^^^^^^^^^^^^^^^^^^^^^^^^^^^^^^^^^^^^^^^^^^^^^^^^^^^^^^^^^^^^^^^^^^^^^^
  File "/home/apiasecz/programming/Federated_Learning_Base_Toolkit_torch/fl_toolkit/models/base_model.py", line 95, in update_steps
    loss.backward()
  File "/home/apiasecz/.conda/envs/cog_fl_llm_env/lib/python3.12/site-packages/torch/_tensor.py", line 525, in backward
    torch.autograd.backward(
  File "/home/apiasecz/.conda/envs/cog_fl_llm_env/lib/python3.12/site-packages/torch/autograd/__init__.py", line 267, in backward
    _engine_run_backward(
  File "/home/apiasecz/.conda/envs/cog_fl_llm_env/lib/python3.12/site-packages/torch/autograd/graph.py", line 744, in _engine_run_backward
    return Variable._execution_engine.run_backward(  # Calls into the C++ engine to run the backward pass
           ^^^^^^^^^^^^^^^^^^^^^^^^^^^^^^^^^^^^^^^^^^^^^^^^^^^^^^^^^^^^^^^^^^^^^^^^^^^^^^^^^^^^^^^^^^^^^^
RuntimeError: cuDNN error: CUDNN_STATUS_NOT_INITIALIZED
Exception in thread Thread-27 (_pin_memory_loop):
Traceback (most recent call last):
  File "/home/apiasecz/.conda/envs/cog_fl_llm_env/lib/python3.12/threading.py", line 1073, in _bootstrap_inner
    self.run()
  File "/home/apiasecz/.conda/envs/cog_fl_llm_env/lib/python3.12/threading.py", line 1010, in run
    self._target(*self._args, **self._kwargs)
  File "/home/apiasecz/.conda/envs/cog_fl_llm_env/lib/python3.12/site-packages/torch/utils/data/_utils/pin_memory.py", line 54, in _pin_memory_loop
    do_one_step()
  File "/home/apiasecz/.conda/envs/cog_fl_llm_env/lib/python3.12/site-packages/torch/utils/data/_utils/pin_memory.py", line 31, in do_one_step
    r = in_queue.get(timeout=MP_STATUS_CHECK_INTERVAL)
        ^^^^^^^^^^^^^^^^^^^^^^^^^^^^^^^^^^^^^^^^^^^^^^
  File "/home/apiasecz/.conda/envs/cog_fl_llm_env/lib/python3.12/multiprocessing/queues.py", line 122, in get
    return _ForkingPickler.loads(res)
           ^^^^^^^^^^^^^^^^^^^^^^^^^^
  File "/home/apiasecz/.conda/envs/cog_fl_llm_env/lib/python3.12/site-packages/torch/multiprocessing/reductions.py", line 495, in rebuild_storage_fd
    fd = df.detach()
         ^^^^^^^^^^^
  File "/home/apiasecz/.conda/envs/cog_fl_llm_env/lib/python3.12/multiprocessing/resource_sharer.py", line 57, in detach
    with _resource_sharer.get_connection(self._id) as conn:
         ^^^^^^^^^^^^^^^^^^^^^^^^^^^^^^^^^^^^^^^^^
  File "/home/apiasecz/.conda/envs/cog_fl_llm_env/lib/python3.12/multiprocessing/resource_sharer.py", line 86, in get_connection
    c = Client(address, authkey=process.current_process().authkey)
        ^^^^^^^^^^^^^^^^^^^^^^^^^^^^^^^^^^^^^^^^^^^^^^^^^^^^^^^^^^
  File "/home/apiasecz/.conda/envs/cog_fl_llm_env/lib/python3.12/multiprocessing/connection.py", line 525, in Client
    answer_challenge(c, authkey)
  File "/home/apiasecz/.conda/envs/cog_fl_llm_env/lib/python3.12/multiprocessing/connection.py", line 953, in answer_challenge
    message = connection.recv_bytes(256)         # reject large message
              ^^^^^^^^^^^^^^^^^^^^^^^^^^
  File "/home/apiasecz/.conda/envs/cog_fl_llm_env/lib/python3.12/multiprocessing/connection.py", line 216, in recv_bytes
    buf = self._recv_bytes(maxlength)
          ^^^^^^^^^^^^^^^^^^^^^^^^^^^
  File "/home/apiasecz/.conda/envs/cog_fl_llm_env/lib/python3.12/multiprocessing/connection.py", line 430, in _recv_bytes
    buf = self._recv(4)
          ^^^^^^^^^^^^^
  File "/home/apiasecz/.conda/envs/cog_fl_llm_env/lib/python3.12/multiprocessing/connection.py", line 395, in _recv
    chunk = read(handle, remaining)
            ^^^^^^^^^^^^^^^^^^^^^^^
ConnectionResetError: [Errno 104] Connection reset by peer
